[2024-10-30T00:49:49.885+0000] {local_task_job_runner.py:123} INFO - ::group::Pre task execution logs
[2024-10-30T00:49:49.975+0000] {taskinstance.py:2612} INFO - Dependencies all met for dep_context=non-requeueable deps ti=<TaskInstance: postgres_to_redshift_etl.load_task scheduled__2024-10-29T00:00:00+00:00 [queued]>
[2024-10-30T00:49:50.015+0000] {taskinstance.py:2612} INFO - Dependencies all met for dep_context=requeueable deps ti=<TaskInstance: postgres_to_redshift_etl.load_task scheduled__2024-10-29T00:00:00+00:00 [queued]>
[2024-10-30T00:49:50.027+0000] {taskinstance.py:2865} INFO - Starting attempt 1 of 1
[2024-10-30T00:49:50.097+0000] {taskinstance.py:2888} INFO - Executing <Task(PythonOperator): load_task> on 2024-10-29 00:00:00+00:00
[2024-10-30T00:49:50.118+0000] {warnings.py:112} WARNING - /home/***/.local/lib/python3.12/site-packages/***/task/task_runner/standard_task_runner.py:70: DeprecationWarning: This process (pid=67) is multi-threaded, use of fork() may lead to deadlocks in the child.
  pid = os.fork()

[2024-10-30T00:49:50.123+0000] {standard_task_runner.py:72} INFO - Started process 68 to run task
[2024-10-30T00:49:50.142+0000] {standard_task_runner.py:104} INFO - Running: ['***', 'tasks', 'run', 'postgres_to_redshift_etl', 'load_task', 'scheduled__2024-10-29T00:00:00+00:00', '--job-id', '210', '--raw', '--subdir', 'DAGS_FOLDER/reds.py', '--cfg-path', '/tmp/tmp_5gik9er']
[2024-10-30T00:49:50.146+0000] {standard_task_runner.py:105} INFO - Job 210: Subtask load_task
[2024-10-30T00:49:52.117+0000] {task_command.py:467} INFO - Running <TaskInstance: postgres_to_redshift_etl.load_task scheduled__2024-10-29T00:00:00+00:00 [running]> on host 7bbdde9419fb
[2024-10-30T00:49:52.928+0000] {taskinstance.py:3131} INFO - Exporting env vars: AIRFLOW_CTX_DAG_OWNER='***' AIRFLOW_CTX_DAG_ID='postgres_to_redshift_etl' AIRFLOW_CTX_TASK_ID='load_task' AIRFLOW_CTX_EXECUTION_DATE='2024-10-29T00:00:00+00:00' AIRFLOW_CTX_TRY_NUMBER='1' AIRFLOW_CTX_DAG_RUN_ID='scheduled__2024-10-29T00:00:00+00:00'
[2024-10-30T00:49:52.997+0000] {taskinstance.py:731} INFO - ::endgroup::
[2024-10-30T00:49:53.427+0000] {base.py:84} INFO - Retrieving connection 'aws_reds_conn'
[2024-10-30T00:50:38.100+0000] {taskinstance.py:3310} ERROR - Task failed with exception
Traceback (most recent call last):
  File "/home/airflow/.local/lib/python3.12/site-packages/airflow/models/taskinstance.py", line 767, in _execute_task
    result = _execute_callable(context=context, **execute_callable_kwargs)
             ^^^^^^^^^^^^^^^^^^^^^^^^^^^^^^^^^^^^^^^^^^^^^^^^^^^^^^^^^^^^^
  File "/home/airflow/.local/lib/python3.12/site-packages/airflow/models/taskinstance.py", line 733, in _execute_callable
    return ExecutionCallableRunner(
           ^^^^^^^^^^^^^^^^^^^^^^^^
  File "/home/airflow/.local/lib/python3.12/site-packages/airflow/utils/operator_helpers.py", line 252, in run
    return self.func(*args, **kwargs)
           ^^^^^^^^^^^^^^^^^^^^^^^^^^
  File "/home/airflow/.local/lib/python3.12/site-packages/airflow/models/baseoperator.py", line 406, in wrapper
    return func(self, *args, **kwargs)
           ^^^^^^^^^^^^^^^^^^^^^^^^^^^
  File "/home/airflow/.local/lib/python3.12/site-packages/airflow/operators/python.py", line 238, in execute
    return_value = self.execute_callable()
                   ^^^^^^^^^^^^^^^^^^^^^^^
  File "/home/airflow/.local/lib/python3.12/site-packages/airflow/operators/python.py", line 256, in execute_callable
    return runner.run(*self.op_args, **self.op_kwargs)
           ^^^^^^^^^^^^^^^^^^^^^^^^^^^^^^^^^^^^^^^^^^^
  File "/home/airflow/.local/lib/python3.12/site-packages/airflow/utils/operator_helpers.py", line 252, in run
    return self.func(*args, **kwargs)
           ^^^^^^^^^^^^^^^^^^^^^^^^^^
  File "/opt/airflow/dags/reds.py", line 44, in load_to_redshift
    conn_rs = psycopg2.connect(
              ^^^^^^^^^^^^^^^^^
  File "/home/airflow/.local/lib/python3.12/site-packages/psycopg2/__init__.py", line 122, in connect
    conn = _connect(dsn, connection_factory=connection_factory, **kwasync)
           ^^^^^^^^^^^^^^^^^^^^^^^^^^^^^^^^^^^^^^^^^^^^^^^^^^^^^^^^^^^^^^^
psycopg2.OperationalError: connection to server at "default-workgroup.471112745066.ap-southeast-2.redshift-serverless.amazonaws.com" (3.105.136.166), port 5439 failed: Connection refused
	Is the server running on that host and accepting TCP/IP connections?
connection to server at "default-workgroup.471112745066.ap-southeast-2.redshift-serverless.amazonaws.com" (3.105.136.166), port 5439 failed: Connection refused
	Is the server running on that host and accepting TCP/IP connections?

[2024-10-30T00:50:38.214+0000] {taskinstance.py:1225} INFO - Marking task as FAILED. dag_id=postgres_to_redshift_etl, task_id=load_task, run_id=scheduled__2024-10-29T00:00:00+00:00, execution_date=20241029T000000, start_date=20241030T004949, end_date=20241030T005038
[2024-10-30T00:50:38.330+0000] {taskinstance.py:340} INFO - ::group::Post task execution logs
[2024-10-30T00:50:38.351+0000] {standard_task_runner.py:124} ERROR - Failed to execute job 210 for task load_task (connection to server at "default-workgroup.471112745066.ap-southeast-2.redshift-serverless.amazonaws.com" (3.105.136.166), port 5439 failed: Connection refused
	Is the server running on that host and accepting TCP/IP connections?
connection to server at "default-workgroup.471112745066.ap-southeast-2.redshift-serverless.amazonaws.com" (3.105.136.166), port 5439 failed: Connection refused
	Is the server running on that host and accepting TCP/IP connections?
; 68)
Traceback (most recent call last):
  File "/home/airflow/.local/lib/python3.12/site-packages/airflow/task/task_runner/standard_task_runner.py", line 117, in _start_by_fork
    ret = args.func(args, dag=self.dag)
          ^^^^^^^^^^^^^^^^^^^^^^^^^^^^^
  File "/home/airflow/.local/lib/python3.12/site-packages/airflow/cli/cli_config.py", line 49, in command
    return func(*args, **kwargs)
           ^^^^^^^^^^^^^^^^^^^^^
  File "/home/airflow/.local/lib/python3.12/site-packages/airflow/utils/cli.py", line 115, in wrapper
    return f(*args, **kwargs)
           ^^^^^^^^^^^^^^^^^^
  File "/home/airflow/.local/lib/python3.12/site-packages/airflow/cli/commands/task_command.py", line 483, in task_run
    task_return_code = _run_task_by_selected_method(args, _dag, ti)
                       ^^^^^^^^^^^^^^^^^^^^^^^^^^^^^^^^^^^^^^^^^^^^
  File "/home/airflow/.local/lib/python3.12/site-packages/airflow/cli/commands/task_command.py", line 256, in _run_task_by_selected_method
    return _run_raw_task(args, ti)
           ^^^^^^^^^^^^^^^^^^^^^^^
  File "/home/airflow/.local/lib/python3.12/site-packages/airflow/cli/commands/task_command.py", line 341, in _run_raw_task
    return ti._run_raw_task(
           ^^^^^^^^^^^^^^^^^
  File "/home/airflow/.local/lib/python3.12/site-packages/airflow/utils/session.py", line 97, in wrapper
    return func(*args, session=session, **kwargs)
           ^^^^^^^^^^^^^^^^^^^^^^^^^^^^^^^^^^^^^^
  File "/home/airflow/.local/lib/python3.12/site-packages/airflow/models/taskinstance.py", line 3004, in _run_raw_task
    return _run_raw_task(
           ^^^^^^^^^^^^^^
  File "/home/airflow/.local/lib/python3.12/site-packages/airflow/models/taskinstance.py", line 273, in _run_raw_task
    TaskInstance._execute_task_with_callbacks(
  File "/home/airflow/.local/lib/python3.12/site-packages/airflow/models/taskinstance.py", line 3158, in _execute_task_with_callbacks
    result = self._execute_task(context, task_orig)
             ^^^^^^^^^^^^^^^^^^^^^^^^^^^^^^^^^^^^^^
  File "/home/airflow/.local/lib/python3.12/site-packages/airflow/models/taskinstance.py", line 3182, in _execute_task
    return _execute_task(self, context, task_orig)
           ^^^^^^^^^^^^^^^^^^^^^^^^^^^^^^^^^^^^^^^
  File "/home/airflow/.local/lib/python3.12/site-packages/airflow/models/taskinstance.py", line 767, in _execute_task
    result = _execute_callable(context=context, **execute_callable_kwargs)
             ^^^^^^^^^^^^^^^^^^^^^^^^^^^^^^^^^^^^^^^^^^^^^^^^^^^^^^^^^^^^^
  File "/home/airflow/.local/lib/python3.12/site-packages/airflow/models/taskinstance.py", line 733, in _execute_callable
    return ExecutionCallableRunner(
           ^^^^^^^^^^^^^^^^^^^^^^^^
  File "/home/airflow/.local/lib/python3.12/site-packages/airflow/utils/operator_helpers.py", line 252, in run
    return self.func(*args, **kwargs)
           ^^^^^^^^^^^^^^^^^^^^^^^^^^
  File "/home/airflow/.local/lib/python3.12/site-packages/airflow/models/baseoperator.py", line 406, in wrapper
    return func(self, *args, **kwargs)
           ^^^^^^^^^^^^^^^^^^^^^^^^^^^
  File "/home/airflow/.local/lib/python3.12/site-packages/airflow/operators/python.py", line 238, in execute
    return_value = self.execute_callable()
                   ^^^^^^^^^^^^^^^^^^^^^^^
  File "/home/airflow/.local/lib/python3.12/site-packages/airflow/operators/python.py", line 256, in execute_callable
    return runner.run(*self.op_args, **self.op_kwargs)
           ^^^^^^^^^^^^^^^^^^^^^^^^^^^^^^^^^^^^^^^^^^^
  File "/home/airflow/.local/lib/python3.12/site-packages/airflow/utils/operator_helpers.py", line 252, in run
    return self.func(*args, **kwargs)
           ^^^^^^^^^^^^^^^^^^^^^^^^^^
  File "/opt/airflow/dags/reds.py", line 44, in load_to_redshift
    conn_rs = psycopg2.connect(
              ^^^^^^^^^^^^^^^^^
  File "/home/airflow/.local/lib/python3.12/site-packages/psycopg2/__init__.py", line 122, in connect
    conn = _connect(dsn, connection_factory=connection_factory, **kwasync)
           ^^^^^^^^^^^^^^^^^^^^^^^^^^^^^^^^^^^^^^^^^^^^^^^^^^^^^^^^^^^^^^^
psycopg2.OperationalError: connection to server at "default-workgroup.471112745066.ap-southeast-2.redshift-serverless.amazonaws.com" (3.105.136.166), port 5439 failed: Connection refused
	Is the server running on that host and accepting TCP/IP connections?
connection to server at "default-workgroup.471112745066.ap-southeast-2.redshift-serverless.amazonaws.com" (3.105.136.166), port 5439 failed: Connection refused
	Is the server running on that host and accepting TCP/IP connections?

[2024-10-30T00:50:38.494+0000] {local_task_job_runner.py:266} INFO - Task exited with return code 1
[2024-10-30T00:50:38.558+0000] {taskinstance.py:3900} INFO - 0 downstream tasks scheduled from follow-on schedule check
[2024-10-30T00:50:38.576+0000] {local_task_job_runner.py:245} INFO - ::endgroup::
