[2024-10-28T05:16:47.786+0000] {local_task_job_runner.py:123} INFO - ::group::Pre task execution logs
[2024-10-28T05:16:47.811+0000] {taskinstance.py:2612} INFO - Dependencies all met for dep_context=non-requeueable deps ti=<TaskInstance: postgres_to_snowflake_etl.load_task manual__2024-10-28T05:16:35.687681+00:00 [queued]>
[2024-10-28T05:16:47.824+0000] {taskinstance.py:2612} INFO - Dependencies all met for dep_context=requeueable deps ti=<TaskInstance: postgres_to_snowflake_etl.load_task manual__2024-10-28T05:16:35.687681+00:00 [queued]>
[2024-10-28T05:16:47.825+0000] {taskinstance.py:2865} INFO - Starting attempt 1 of 1
[2024-10-28T05:16:47.849+0000] {taskinstance.py:2888} INFO - Executing <Task(PythonOperator): load_task> on 2024-10-28 05:16:35.687681+00:00
[2024-10-28T05:16:47.859+0000] {warnings.py:112} WARNING - /home/***/.local/lib/python3.12/site-packages/***/task/task_runner/standard_task_runner.py:70: DeprecationWarning: This process (pid=83) is multi-threaded, use of fork() may lead to deadlocks in the child.
  pid = os.fork()

[2024-10-28T05:16:47.862+0000] {standard_task_runner.py:72} INFO - Started process 85 to run task
[2024-10-28T05:16:47.862+0000] {standard_task_runner.py:104} INFO - Running: ['***', 'tasks', 'run', 'postgres_to_snowflake_etl', 'load_task', 'manual__2024-10-28T05:16:35.687681+00:00', '--job-id', '81', '--raw', '--subdir', 'DAGS_FOLDER/pg_sf.py', '--cfg-path', '/tmp/tmpin_uwjgj']
[2024-10-28T05:16:47.869+0000] {standard_task_runner.py:105} INFO - Job 81: Subtask load_task
[2024-10-28T05:16:48.003+0000] {task_command.py:467} INFO - Running <TaskInstance: postgres_to_snowflake_etl.load_task manual__2024-10-28T05:16:35.687681+00:00 [running]> on host d944eca59341
[2024-10-28T05:16:48.165+0000] {taskinstance.py:3131} INFO - Exporting env vars: AIRFLOW_CTX_DAG_OWNER='***' AIRFLOW_CTX_DAG_ID='postgres_to_snowflake_etl' AIRFLOW_CTX_TASK_ID='load_task' AIRFLOW_CTX_EXECUTION_DATE='2024-10-28T05:16:35.687681+00:00' AIRFLOW_CTX_TRY_NUMBER='1' AIRFLOW_CTX_DAG_RUN_ID='manual__2024-10-28T05:16:35.687681+00:00'
[2024-10-28T05:16:48.167+0000] {taskinstance.py:731} INFO - ::endgroup::
[2024-10-28T05:16:48.236+0000] {base.py:84} INFO - Retrieving connection 'sf_conn'
[2024-10-28T05:16:48.237+0000] {connection.py:413} INFO - Snowflake Connector for Python Version: 3.12.2, Python Version: 3.12.6, Platform: Linux-5.15.133.1-microsoft-standard-WSL2-x86_64-with-glibc2.36
[2024-10-28T05:16:48.239+0000] {connection.py:1196} INFO - Connecting to GLOBAL Snowflake domain
[2024-10-28T05:16:48.240+0000] {connection.py:1277} INFO - This connection is in OCSP Fail Open Mode. TLS Certificates would be checked for validity and revocation status. Any other Certificate Revocation related exceptions or OCSP Responder failures would be disregarded in favor of connectivity.
[2024-10-28T05:16:51.610+0000] {connectionpool.py:824} WARNING - Retrying (Retry(total=0, connect=None, read=None, redirect=None, status=None)) after connection broken by 'NewConnectionError('<snowflake.connector.vendored.urllib3.connection.HTTPSConnection object at 0x7febe487e6c0>: Failed to establish a new connection: [Errno -2] Name or service not known')': //la76566.ap-southeast-3.snowflakecomputing.com.snowflakecomputing.com:443/session/v1/login-request?request_id=d34e715f-d6ab-4e15-afc0-c1dbc071827f&databaseName=STORE&schemaName=DEALER&warehouse=COMPUTE_WH
[2024-10-28T05:16:59.654+0000] {connectionpool.py:824} WARNING - Retrying (Retry(total=0, connect=None, read=None, redirect=None, status=None)) after connection broken by 'NewConnectionError('<snowflake.connector.vendored.urllib3.connection.HTTPSConnection object at 0x7febe44da840>: Failed to establish a new connection: [Errno -2] Name or service not known')': //la76566.ap-southeast-3.snowflakecomputing.com.snowflakecomputing.com:443/session/v1/login-request?request_id=1847b759-9995-4acf-8100-1f4e63d5be13&databaseName=STORE&schemaName=DEALER&warehouse=COMPUTE_WH
[2024-10-28T05:17:02.976+0000] {taskinstance.py:3310} ERROR - Task failed with exception
Traceback (most recent call last):
  File "/home/airflow/.local/lib/python3.12/site-packages/snowflake/connector/vendored/urllib3/connection.py", line 174, in _new_conn
    conn = connection.create_connection(
           ^^^^^^^^^^^^^^^^^^^^^^^^^^^^^
  File "/home/airflow/.local/lib/python3.12/site-packages/snowflake/connector/vendored/urllib3/util/connection.py", line 79, in create_connection
    for res in socket.getaddrinfo(host, port, family, socket.SOCK_STREAM):
               ^^^^^^^^^^^^^^^^^^^^^^^^^^^^^^^^^^^^^^^^^^^^^^^^^^^^^^^^^^
  File "/usr/local/lib/python3.12/socket.py", line 976, in getaddrinfo
    for res in _socket.getaddrinfo(host, port, family, type, proto, flags):
               ^^^^^^^^^^^^^^^^^^^^^^^^^^^^^^^^^^^^^^^^^^^^^^^^^^^^^^^^^^^
socket.gaierror: [Errno -2] Name or service not known

During handling of the above exception, another exception occurred:

Traceback (most recent call last):
  File "/home/airflow/.local/lib/python3.12/site-packages/snowflake/connector/vendored/urllib3/connectionpool.py", line 715, in urlopen
    httplib_response = self._make_request(
                       ^^^^^^^^^^^^^^^^^^^
  File "/home/airflow/.local/lib/python3.12/site-packages/snowflake/connector/vendored/urllib3/connectionpool.py", line 404, in _make_request
    self._validate_conn(conn)
  File "/home/airflow/.local/lib/python3.12/site-packages/snowflake/connector/vendored/urllib3/connectionpool.py", line 1058, in _validate_conn
    conn.connect()
  File "/home/airflow/.local/lib/python3.12/site-packages/snowflake/connector/vendored/urllib3/connection.py", line 363, in connect
    self.sock = conn = self._new_conn()
                       ^^^^^^^^^^^^^^^^
  File "/home/airflow/.local/lib/python3.12/site-packages/snowflake/connector/vendored/urllib3/connection.py", line 186, in _new_conn
    raise NewConnectionError(
snowflake.connector.vendored.urllib3.exceptions.NewConnectionError: <snowflake.connector.vendored.urllib3.connection.HTTPSConnection object at 0x7febe45d2bd0>: Failed to establish a new connection: [Errno -2] Name or service not known

During handling of the above exception, another exception occurred:

Traceback (most recent call last):
  File "/home/airflow/.local/lib/python3.12/site-packages/snowflake/connector/vendored/requests/adapters.py", line 486, in send
    resp = conn.urlopen(
           ^^^^^^^^^^^^^
  File "/home/airflow/.local/lib/python3.12/site-packages/snowflake/connector/vendored/urllib3/connectionpool.py", line 827, in urlopen
    return self.urlopen(
           ^^^^^^^^^^^^^
  File "/home/airflow/.local/lib/python3.12/site-packages/snowflake/connector/vendored/urllib3/connectionpool.py", line 799, in urlopen
    retries = retries.increment(
              ^^^^^^^^^^^^^^^^^^
  File "/home/airflow/.local/lib/python3.12/site-packages/snowflake/connector/vendored/urllib3/util/retry.py", line 592, in increment
    raise MaxRetryError(_pool, url, error or ResponseError(cause))
snowflake.connector.vendored.urllib3.exceptions.MaxRetryError: HTTPSConnectionPool(host='https', port=443): Max retries exceeded with url: //la76566.ap-southeast-3.snowflakecomputing.com.snowflakecomputing.com:443/session/v1/login-request?request_id=d34e715f-d6ab-4e15-afc0-c1dbc071827f&databaseName=STORE&schemaName=DEALER&warehouse=COMPUTE_WH (Caused by NewConnectionError('<snowflake.connector.vendored.urllib3.connection.HTTPSConnection object at 0x7febe45d2bd0>: Failed to establish a new connection: [Errno -2] Name or service not known'))

During handling of the above exception, another exception occurred:

Traceback (most recent call last):
  File "/home/airflow/.local/lib/python3.12/site-packages/snowflake/connector/network.py", line 1071, in _request_exec
    raw_ret = session.request(
              ^^^^^^^^^^^^^^^^
  File "/home/airflow/.local/lib/python3.12/site-packages/snowflake/connector/vendored/requests/sessions.py", line 589, in request
    resp = self.send(prep, **send_kwargs)
           ^^^^^^^^^^^^^^^^^^^^^^^^^^^^^^
  File "/home/airflow/.local/lib/python3.12/site-packages/snowflake/connector/vendored/requests/sessions.py", line 703, in send
    r = adapter.send(request, **kwargs)
        ^^^^^^^^^^^^^^^^^^^^^^^^^^^^^^^
  File "/home/airflow/.local/lib/python3.12/site-packages/snowflake/connector/vendored/requests/adapters.py", line 519, in send
    raise ConnectionError(e, request=request)
snowflake.connector.vendored.requests.exceptions.ConnectionError: HTTPSConnectionPool(host='https', port=443): Max retries exceeded with url: //la76566.ap-southeast-3.snowflakecomputing.com.snowflakecomputing.com:443/session/v1/login-request?request_id=d34e715f-d6ab-4e15-afc0-c1dbc071827f&databaseName=STORE&schemaName=DEALER&warehouse=COMPUTE_WH (Caused by NewConnectionError('<snowflake.connector.vendored.urllib3.connection.HTTPSConnection object at 0x7febe45d2bd0>: Failed to establish a new connection: [Errno -2] Name or service not known'))

During handling of the above exception, another exception occurred:

Traceback (most recent call last):
  File "/home/airflow/.local/lib/python3.12/site-packages/snowflake/connector/connection.py", line 1414, in _authenticate
    auth.authenticate(
  File "/home/airflow/.local/lib/python3.12/site-packages/snowflake/connector/auth/_auth.py", line 250, in authenticate
    ret = self._rest._post_request(
          ^^^^^^^^^^^^^^^^^^^^^^^^^
  File "/home/airflow/.local/lib/python3.12/site-packages/snowflake/connector/network.py", line 739, in _post_request
    ret = self.fetch(
          ^^^^^^^^^^^
  File "/home/airflow/.local/lib/python3.12/site-packages/snowflake/connector/network.py", line 854, in fetch
    ret = self._request_exec_wrapper(
          ^^^^^^^^^^^^^^^^^^^^^^^^^^^
  File "/home/airflow/.local/lib/python3.12/site-packages/snowflake/connector/network.py", line 982, in _request_exec_wrapper
    raise e
  File "/home/airflow/.local/lib/python3.12/site-packages/snowflake/connector/network.py", line 904, in _request_exec_wrapper
    return_object = self._request_exec(
                    ^^^^^^^^^^^^^^^^^^^
  File "/home/airflow/.local/lib/python3.12/site-packages/snowflake/connector/network.py", line 1158, in _request_exec
    raise OperationalError(
snowflake.connector.errors.OperationalError: 251011: 251011: ConnectionTimeout occurred during login. Will be handled by authenticator

The above exception was the direct cause of the following exception:

Traceback (most recent call last):
  File "/home/airflow/.local/lib/python3.12/site-packages/airflow/models/taskinstance.py", line 767, in _execute_task
    result = _execute_callable(context=context, **execute_callable_kwargs)
             ^^^^^^^^^^^^^^^^^^^^^^^^^^^^^^^^^^^^^^^^^^^^^^^^^^^^^^^^^^^^^
  File "/home/airflow/.local/lib/python3.12/site-packages/airflow/models/taskinstance.py", line 733, in _execute_callable
    return ExecutionCallableRunner(
           ^^^^^^^^^^^^^^^^^^^^^^^^
  File "/home/airflow/.local/lib/python3.12/site-packages/airflow/utils/operator_helpers.py", line 252, in run
    return self.func(*args, **kwargs)
           ^^^^^^^^^^^^^^^^^^^^^^^^^^
  File "/home/airflow/.local/lib/python3.12/site-packages/airflow/models/baseoperator.py", line 406, in wrapper
    return func(self, *args, **kwargs)
           ^^^^^^^^^^^^^^^^^^^^^^^^^^^
  File "/home/airflow/.local/lib/python3.12/site-packages/airflow/operators/python.py", line 238, in execute
    return_value = self.execute_callable()
                   ^^^^^^^^^^^^^^^^^^^^^^^
  File "/home/airflow/.local/lib/python3.12/site-packages/airflow/operators/python.py", line 256, in execute_callable
    return runner.run(*self.op_args, **self.op_kwargs)
           ^^^^^^^^^^^^^^^^^^^^^^^^^^^^^^^^^^^^^^^^^^^
  File "/home/airflow/.local/lib/python3.12/site-packages/airflow/utils/operator_helpers.py", line 252, in run
    return self.func(*args, **kwargs)
           ^^^^^^^^^^^^^^^^^^^^^^^^^^
  File "/opt/airflow/dags/pg_sf.py", line 44, in load_to_snowflake
    conn_sf = snowflake.connector.connect(
              ^^^^^^^^^^^^^^^^^^^^^^^^^^^^
  File "/home/airflow/.local/lib/python3.12/site-packages/snowflake/connector/__init__.py", line 55, in Connect
    return SnowflakeConnection(**kwargs)
           ^^^^^^^^^^^^^^^^^^^^^^^^^^^^^
  File "/home/airflow/.local/lib/python3.12/site-packages/snowflake/connector/connection.py", line 456, in __init__
    self.connect(**kwargs)
  File "/home/airflow/.local/lib/python3.12/site-packages/snowflake/connector/connection.py", line 771, in connect
    self.__open_connection()
  File "/home/airflow/.local/lib/python3.12/site-packages/snowflake/connector/connection.py", line 1099, in __open_connection
    self.authenticate_with_retry(self.auth_class)
  File "/home/airflow/.local/lib/python3.12/site-packages/snowflake/connector/connection.py", line 1386, in authenticate_with_retry
    self._authenticate(auth_instance)
  File "/home/airflow/.local/lib/python3.12/site-packages/snowflake/connector/connection.py", line 1458, in _authenticate
    raise auth_op from e
  File "/home/airflow/.local/lib/python3.12/site-packages/snowflake/connector/connection.py", line 1435, in _authenticate
    auth_instance.handle_timeout(
  File "/home/airflow/.local/lib/python3.12/site-packages/snowflake/connector/auth/by_plugin.py", line 212, in handle_timeout
    raise error
snowflake.connector.errors.OperationalError: 250001: 250001: Could not connect to Snowflake backend after 2 attempt(s).Aborting
[2024-10-28T05:17:03.046+0000] {taskinstance.py:1225} INFO - Marking task as FAILED. dag_id=postgres_to_snowflake_etl, task_id=load_task, run_id=manual__2024-10-28T05:16:35.687681+00:00, execution_date=20241028T051635, start_date=20241028T051647, end_date=20241028T051703
[2024-10-28T05:17:03.125+0000] {taskinstance.py:340} INFO - ::group::Post task execution logs
[2024-10-28T05:17:03.126+0000] {standard_task_runner.py:124} ERROR - Failed to execute job 81 for task load_task (250001: 250001: Could not connect to Snowflake backend after 2 attempt(s).Aborting; 85)
Traceback (most recent call last):
  File "/home/airflow/.local/lib/python3.12/site-packages/snowflake/connector/vendored/urllib3/connection.py", line 174, in _new_conn
    conn = connection.create_connection(
           ^^^^^^^^^^^^^^^^^^^^^^^^^^^^^
  File "/home/airflow/.local/lib/python3.12/site-packages/snowflake/connector/vendored/urllib3/util/connection.py", line 79, in create_connection
    for res in socket.getaddrinfo(host, port, family, socket.SOCK_STREAM):
               ^^^^^^^^^^^^^^^^^^^^^^^^^^^^^^^^^^^^^^^^^^^^^^^^^^^^^^^^^^
  File "/usr/local/lib/python3.12/socket.py", line 976, in getaddrinfo
    for res in _socket.getaddrinfo(host, port, family, type, proto, flags):
               ^^^^^^^^^^^^^^^^^^^^^^^^^^^^^^^^^^^^^^^^^^^^^^^^^^^^^^^^^^^
socket.gaierror: [Errno -2] Name or service not known

During handling of the above exception, another exception occurred:

Traceback (most recent call last):
  File "/home/airflow/.local/lib/python3.12/site-packages/snowflake/connector/vendored/urllib3/connectionpool.py", line 715, in urlopen
    httplib_response = self._make_request(
                       ^^^^^^^^^^^^^^^^^^^
  File "/home/airflow/.local/lib/python3.12/site-packages/snowflake/connector/vendored/urllib3/connectionpool.py", line 404, in _make_request
    self._validate_conn(conn)
  File "/home/airflow/.local/lib/python3.12/site-packages/snowflake/connector/vendored/urllib3/connectionpool.py", line 1058, in _validate_conn
    conn.connect()
  File "/home/airflow/.local/lib/python3.12/site-packages/snowflake/connector/vendored/urllib3/connection.py", line 363, in connect
    self.sock = conn = self._new_conn()
                       ^^^^^^^^^^^^^^^^
  File "/home/airflow/.local/lib/python3.12/site-packages/snowflake/connector/vendored/urllib3/connection.py", line 186, in _new_conn
    raise NewConnectionError(
snowflake.connector.vendored.urllib3.exceptions.NewConnectionError: <snowflake.connector.vendored.urllib3.connection.HTTPSConnection object at 0x7febe45d2bd0>: Failed to establish a new connection: [Errno -2] Name or service not known

During handling of the above exception, another exception occurred:

Traceback (most recent call last):
  File "/home/airflow/.local/lib/python3.12/site-packages/snowflake/connector/vendored/requests/adapters.py", line 486, in send
    resp = conn.urlopen(
           ^^^^^^^^^^^^^
  File "/home/airflow/.local/lib/python3.12/site-packages/snowflake/connector/vendored/urllib3/connectionpool.py", line 827, in urlopen
    return self.urlopen(
           ^^^^^^^^^^^^^
  File "/home/airflow/.local/lib/python3.12/site-packages/snowflake/connector/vendored/urllib3/connectionpool.py", line 799, in urlopen
    retries = retries.increment(
              ^^^^^^^^^^^^^^^^^^
  File "/home/airflow/.local/lib/python3.12/site-packages/snowflake/connector/vendored/urllib3/util/retry.py", line 592, in increment
    raise MaxRetryError(_pool, url, error or ResponseError(cause))
snowflake.connector.vendored.urllib3.exceptions.MaxRetryError: HTTPSConnectionPool(host='https', port=443): Max retries exceeded with url: //la76566.ap-southeast-3.snowflakecomputing.com.snowflakecomputing.com:443/session/v1/login-request?request_id=d34e715f-d6ab-4e15-afc0-c1dbc071827f&databaseName=STORE&schemaName=DEALER&warehouse=COMPUTE_WH (Caused by NewConnectionError('<snowflake.connector.vendored.urllib3.connection.HTTPSConnection object at 0x7febe45d2bd0>: Failed to establish a new connection: [Errno -2] Name or service not known'))

During handling of the above exception, another exception occurred:

Traceback (most recent call last):
  File "/home/airflow/.local/lib/python3.12/site-packages/snowflake/connector/network.py", line 1071, in _request_exec
    raw_ret = session.request(
              ^^^^^^^^^^^^^^^^
  File "/home/airflow/.local/lib/python3.12/site-packages/snowflake/connector/vendored/requests/sessions.py", line 589, in request
    resp = self.send(prep, **send_kwargs)
           ^^^^^^^^^^^^^^^^^^^^^^^^^^^^^^
  File "/home/airflow/.local/lib/python3.12/site-packages/snowflake/connector/vendored/requests/sessions.py", line 703, in send
    r = adapter.send(request, **kwargs)
        ^^^^^^^^^^^^^^^^^^^^^^^^^^^^^^^
  File "/home/airflow/.local/lib/python3.12/site-packages/snowflake/connector/vendored/requests/adapters.py", line 519, in send
    raise ConnectionError(e, request=request)
snowflake.connector.vendored.requests.exceptions.ConnectionError: HTTPSConnectionPool(host='https', port=443): Max retries exceeded with url: //la76566.ap-southeast-3.snowflakecomputing.com.snowflakecomputing.com:443/session/v1/login-request?request_id=d34e715f-d6ab-4e15-afc0-c1dbc071827f&databaseName=STORE&schemaName=DEALER&warehouse=COMPUTE_WH (Caused by NewConnectionError('<snowflake.connector.vendored.urllib3.connection.HTTPSConnection object at 0x7febe45d2bd0>: Failed to establish a new connection: [Errno -2] Name or service not known'))

During handling of the above exception, another exception occurred:

Traceback (most recent call last):
  File "/home/airflow/.local/lib/python3.12/site-packages/snowflake/connector/connection.py", line 1414, in _authenticate
    auth.authenticate(
  File "/home/airflow/.local/lib/python3.12/site-packages/snowflake/connector/auth/_auth.py", line 250, in authenticate
    ret = self._rest._post_request(
          ^^^^^^^^^^^^^^^^^^^^^^^^^
  File "/home/airflow/.local/lib/python3.12/site-packages/snowflake/connector/network.py", line 739, in _post_request
    ret = self.fetch(
          ^^^^^^^^^^^
  File "/home/airflow/.local/lib/python3.12/site-packages/snowflake/connector/network.py", line 854, in fetch
    ret = self._request_exec_wrapper(
          ^^^^^^^^^^^^^^^^^^^^^^^^^^^
  File "/home/airflow/.local/lib/python3.12/site-packages/snowflake/connector/network.py", line 982, in _request_exec_wrapper
    raise e
  File "/home/airflow/.local/lib/python3.12/site-packages/snowflake/connector/network.py", line 904, in _request_exec_wrapper
    return_object = self._request_exec(
                    ^^^^^^^^^^^^^^^^^^^
  File "/home/airflow/.local/lib/python3.12/site-packages/snowflake/connector/network.py", line 1158, in _request_exec
    raise OperationalError(
snowflake.connector.errors.OperationalError: 251011: 251011: ConnectionTimeout occurred during login. Will be handled by authenticator

The above exception was the direct cause of the following exception:

Traceback (most recent call last):
  File "/home/airflow/.local/lib/python3.12/site-packages/airflow/task/task_runner/standard_task_runner.py", line 117, in _start_by_fork
    ret = args.func(args, dag=self.dag)
          ^^^^^^^^^^^^^^^^^^^^^^^^^^^^^
  File "/home/airflow/.local/lib/python3.12/site-packages/airflow/cli/cli_config.py", line 49, in command
    return func(*args, **kwargs)
           ^^^^^^^^^^^^^^^^^^^^^
  File "/home/airflow/.local/lib/python3.12/site-packages/airflow/utils/cli.py", line 115, in wrapper
    return f(*args, **kwargs)
           ^^^^^^^^^^^^^^^^^^
  File "/home/airflow/.local/lib/python3.12/site-packages/airflow/cli/commands/task_command.py", line 483, in task_run
    task_return_code = _run_task_by_selected_method(args, _dag, ti)
                       ^^^^^^^^^^^^^^^^^^^^^^^^^^^^^^^^^^^^^^^^^^^^
  File "/home/airflow/.local/lib/python3.12/site-packages/airflow/cli/commands/task_command.py", line 256, in _run_task_by_selected_method
    return _run_raw_task(args, ti)
           ^^^^^^^^^^^^^^^^^^^^^^^
  File "/home/airflow/.local/lib/python3.12/site-packages/airflow/cli/commands/task_command.py", line 341, in _run_raw_task
    return ti._run_raw_task(
           ^^^^^^^^^^^^^^^^^
  File "/home/airflow/.local/lib/python3.12/site-packages/airflow/utils/session.py", line 97, in wrapper
    return func(*args, session=session, **kwargs)
           ^^^^^^^^^^^^^^^^^^^^^^^^^^^^^^^^^^^^^^
  File "/home/airflow/.local/lib/python3.12/site-packages/airflow/models/taskinstance.py", line 3004, in _run_raw_task
    return _run_raw_task(
           ^^^^^^^^^^^^^^
  File "/home/airflow/.local/lib/python3.12/site-packages/airflow/models/taskinstance.py", line 273, in _run_raw_task
    TaskInstance._execute_task_with_callbacks(
  File "/home/airflow/.local/lib/python3.12/site-packages/airflow/models/taskinstance.py", line 3158, in _execute_task_with_callbacks
    result = self._execute_task(context, task_orig)
             ^^^^^^^^^^^^^^^^^^^^^^^^^^^^^^^^^^^^^^
  File "/home/airflow/.local/lib/python3.12/site-packages/airflow/models/taskinstance.py", line 3182, in _execute_task
    return _execute_task(self, context, task_orig)
           ^^^^^^^^^^^^^^^^^^^^^^^^^^^^^^^^^^^^^^^
  File "/home/airflow/.local/lib/python3.12/site-packages/airflow/models/taskinstance.py", line 767, in _execute_task
    result = _execute_callable(context=context, **execute_callable_kwargs)
             ^^^^^^^^^^^^^^^^^^^^^^^^^^^^^^^^^^^^^^^^^^^^^^^^^^^^^^^^^^^^^
  File "/home/airflow/.local/lib/python3.12/site-packages/airflow/models/taskinstance.py", line 733, in _execute_callable
    return ExecutionCallableRunner(
           ^^^^^^^^^^^^^^^^^^^^^^^^
  File "/home/airflow/.local/lib/python3.12/site-packages/airflow/utils/operator_helpers.py", line 252, in run
    return self.func(*args, **kwargs)
           ^^^^^^^^^^^^^^^^^^^^^^^^^^
  File "/home/airflow/.local/lib/python3.12/site-packages/airflow/models/baseoperator.py", line 406, in wrapper
    return func(self, *args, **kwargs)
           ^^^^^^^^^^^^^^^^^^^^^^^^^^^
  File "/home/airflow/.local/lib/python3.12/site-packages/airflow/operators/python.py", line 238, in execute
    return_value = self.execute_callable()
                   ^^^^^^^^^^^^^^^^^^^^^^^
  File "/home/airflow/.local/lib/python3.12/site-packages/airflow/operators/python.py", line 256, in execute_callable
    return runner.run(*self.op_args, **self.op_kwargs)
           ^^^^^^^^^^^^^^^^^^^^^^^^^^^^^^^^^^^^^^^^^^^
  File "/home/airflow/.local/lib/python3.12/site-packages/airflow/utils/operator_helpers.py", line 252, in run
    return self.func(*args, **kwargs)
           ^^^^^^^^^^^^^^^^^^^^^^^^^^
  File "/opt/airflow/dags/pg_sf.py", line 44, in load_to_snowflake
    conn_sf = snowflake.connector.connect(
              ^^^^^^^^^^^^^^^^^^^^^^^^^^^^
  File "/home/airflow/.local/lib/python3.12/site-packages/snowflake/connector/__init__.py", line 55, in Connect
    return SnowflakeConnection(**kwargs)
           ^^^^^^^^^^^^^^^^^^^^^^^^^^^^^
  File "/home/airflow/.local/lib/python3.12/site-packages/snowflake/connector/connection.py", line 456, in __init__
    self.connect(**kwargs)
  File "/home/airflow/.local/lib/python3.12/site-packages/snowflake/connector/connection.py", line 771, in connect
    self.__open_connection()
  File "/home/airflow/.local/lib/python3.12/site-packages/snowflake/connector/connection.py", line 1099, in __open_connection
    self.authenticate_with_retry(self.auth_class)
  File "/home/airflow/.local/lib/python3.12/site-packages/snowflake/connector/connection.py", line 1386, in authenticate_with_retry
    self._authenticate(auth_instance)
  File "/home/airflow/.local/lib/python3.12/site-packages/snowflake/connector/connection.py", line 1458, in _authenticate
    raise auth_op from e
  File "/home/airflow/.local/lib/python3.12/site-packages/snowflake/connector/connection.py", line 1435, in _authenticate
    auth_instance.handle_timeout(
  File "/home/airflow/.local/lib/python3.12/site-packages/snowflake/connector/auth/by_plugin.py", line 212, in handle_timeout
    raise error
snowflake.connector.errors.OperationalError: 250001: 250001: Could not connect to Snowflake backend after 2 attempt(s).Aborting
[2024-10-28T05:17:03.163+0000] {local_task_job_runner.py:266} INFO - Task exited with return code 1
[2024-10-28T05:17:03.241+0000] {taskinstance.py:3900} INFO - 0 downstream tasks scheduled from follow-on schedule check
[2024-10-28T05:17:03.251+0000] {local_task_job_runner.py:245} INFO - ::endgroup::
